Workbook

Sheet 요약
B2: 재연마수주 납기 현황 보고
B4: 기준일 | C4: 46219 | D4: (ERP 09:00 자동 갱신 파일 기준, 입력값)
B6: 구분 | C6: 값 | D6: 단위
B7: 총 수주 건수 | C7: =COUNTA(원본데이터!A3:A200) -> 102 | D7: 건
B8: 총 수주수량 | C8: =SUM(원본데이터!G3:G200) -> 3429 | D8: 개
B9: 총 출고수량 | C9: =SUM(원본데이터!H3:H200) -> 2112 | D9: 개
B10: 총 미출고 잔량 | C10: =SUM(원본데이터!I3:I200) -> 1317 | D10: 개
B11: 연체 건수 (기준일 이전 납기·미출고) | C11: =COUNTIF(원본데이터!L3:L200,"연체") -> 13 | D11: 건
B12: 연체 잔량 | C12: =SUMIF(원본데이터!L3:L200,"연체",원본데이터!I3:I200) -> 412 | D12: 개
B15: 상태코드별 요약
B16: 상태코드 | C16: 상태명 | D16: 건수 | E16: 수주수량 | F16: 출고수량 | G16: 잔량
B17: SD200000 | C17: 미착수(신규접수) | D17: =COUNTIF(원본데이터!$J$3:$J$200,B17) -> 31 | E17: =SUMIF(원본데이터!$J$3:$J$200,B17,원본데이터!$G$3:$G$200) -> 1127 | F17: =SUMIF(원본데이터!$J$3:$J$200,B17,원본데이터!$H$3:$H$200) -> 0 | G17: =SUMIF(원본데이터!$J$3:$J$200,B17,원본데이터!$I$3:$I$200) -> 1127
B18: SD200100 | C18: 진행중 | D18: =COUNTIF(원본데이터!$J$3:$J$200,B18) -> 5 | E18: =SUMIF(원본데이터!$J$3:$J$200,B18,원본데이터!$G$3:$G$200) -> 170 | F18: =SUMIF(원본데이터!$J$3:$J$200,B18,원본데이터!$H$3:$H$200) -> 0 | G18: =SUMIF(원본데이터!$J$3:$J$200,B18,원본데이터!$I$3:$I$200) -> 170
B19: SD200300 | C19: 부분출고 | D19: =COUNTIF(원본데이터!$J$3:$J$200,B19) -> 2 | E19: =SUMIF(원본데이터!$J$3:$J$200,B19,원본데이터!$G$3:$G$200) -> 30 | F19: =SUMIF(원본데이터!$J$3:$J$200,B19,원본데이터!$H$3:$H$200) -> 7 | G19: =SUMIF(원본데이터!$J$3:$J$200,B19,원본데이터!$I$3:$I$200) -> 23
B20: SD200500 | C20: 출고완료 | D20: =COUNTIF(원본데이터!$J$3:$J$200,B20) -> 64 | E20: =SUMIF(원본데이터!$J$3:$J$200,B20,원본데이터!$G$3:$G$200) -> 2102 | F20: =SUMIF(원본데이터!$J$3:$J$200,B20,원본데이터!$H$3:$H$200) -> 2105 | G20: =SUMIF(원본데이터!$J$3:$J$200,B20,원본데이터!$I$3:$I$200) -> -3
B22: 근거: 미착수(SD200000)·진행중(SD200100)·부분출고(SD200300) 3개 상태는 실제 미출고 잔량이 남아 있음. 출고완료(SD200500)는 잔량이 0에 수렴(반올림 오차 제외) — 사실상 종결.
B23: 신뢰도: 실측 검증(ERP 원본 데이터 직접 계산). daily_dlv_alert.py의 완료 제외 필터(DONE_STAT)가 실제 상태코드와 불일치하는 버그가 있어(확인됨), 본 보고서는 상태코드 기준으로 별도 재계산함.
B24: 출처: outputs/dlv_alerts/납기알림_20260716.xlsx (ERP 재연마수주 등록 조회, 2026-07-16 09:00 자동 생성)

Sheet 일자별집계
A1: 납기일
A3: 납기일 | B3: 건수 | C3: 수주수량 | D3: 출고수량 | E3: 잔량 | F3: 비고
A4: 46175 | B4: =COUNTIF(원본데이터!$C$3:$C$200,A4) -> 2 | C4: =SUMIF(원본데이터!$C$3:$C$200,A4,원본데이터!$G$3:$G$200) -> 94 | D4: =SUMIF(원본데이터!$C$3:$C$200,A4,원본데이터!$H$3:$H$200) -> 94 | E4: =SUMIF(원본데이터!$C$3:$C$200,A4,원본데이터!$I$3:$I$200) -> 0 | F4: =IF(A4<요약!$C$4,IF(E4>0,"연체","완료"),IF(E4>0,"임박/예정","")) -> 완료
A5: 46184 | B5: =COUNTIF(원본데이터!$C$3:$C$200,A5) -> 1 | C5: =SUMIF(원본데이터!$C$3:$C$200,A5,원본데이터!$G$3:$G$200) -> 35 | D5: =SUMIF(원본데이터!$C$3:$C$200,A5,원본데이터!$H$3:$H$200) -> 35 | E5: =SUMIF(원본데이터!$C$3:$C$200,A5,원본데이터!$I$3:$I$200) -> 0 | F5: =IF(A5<요약!$C$4,IF(E5>0,"연체","완료"),IF(E5>0,"임박/예정","")) -> 완료
A6: 46185 | B6: =COUNTIF(원본데이터!$C$3:$C$200,A6) -> 4 | C6: =SUMIF(원본데이터!$C$3:$C$200,A6,원본데이터!$G$3:$G$200) -> 70 | D6: =SUMIF(원본데이터!$C$3:$C$200,A6,원본데이터!$H$3:$H$200) -> 70 | E6: =SUMIF(원본데이터!$C$3:$C$200,A6,원본데이터!$I$3:$I$200) -> 0 | F6: =IF(A6<요약!$C$4,IF(E6>0,"연체","완료"),IF(E6>0,"임박/예정","")) -> 완료
A7: 46187 | B7: =COUNTIF(원본데이터!$C$3:$C$200,A7) -> 2 | C7: =SUMIF(원본데이터!$C$3:$C$200,A7,원본데이터!$G$3:$G$200) -> 10 | D7: =SUMIF(원본데이터!$C$3:$C$200,A7,원본데이터!$H$3:$H$200) -> 10 | E7: =SUMIF(원본데이터!$C$3:$C$200,A7,원본데이터!$I$3:$I$200) -> 0 | F7: =IF(A7<요약!$C$4,IF(E7>0,"연체","완료"),IF(E7>0,"임박/예정","")) -> 완료
A8: 46188 | B8: =COUNTIF(원본데이터!$C$3:$C$200,A8) -> 3 | C8: =SUMIF(원본데이터!$C$3:$C$200,A8,원본데이터!$G$3:$G$200) -> 35 | D8: =SUMIF(원본데이터!$C$3:$C$200,A8,원본데이터!$H$3:$H$200) -> 35 | E8: =SUMIF(원본데이터!$C$3:$C$200,A8,원본데이터!$I$3:$I$200) -> 0 | F8: =IF(A8<요약!$C$4,IF(E8>0,"연체","완료"),IF(E8>0,"임박/예정","")) -> 완료
A9: 46189 | B9: =COUNTIF(원본데이터!$C$3:$C$200,A9) -> 1 | C9: =SUMIF(원본데이터!$C$3:$C$200,A9,원본데이터!$G$3:$G$200) -> 10 | D9: =SUMIF(원본데이터!$C$3:$C$200,A9,원본데이터!$H$3:$H$200) -> 10 | E9: =SUMIF(원본데이터!$C$3:$C$200,A9,원본데이터!$I$3:$I$200) -> 0 | F9: =IF(A9<요약!$C$4,IF(E9>0,"연체","완료"),IF(E9>0,"임박/예정","")) -> 완료
A10: 46191 | B10: =COUNTIF(원본데이터!$C$3:$C$200,A10) -> 2 | C10: =SUMIF(원본데이터!$C$3:$C$200,A10,원본데이터!$G$3:$G$200) -> 23 | D10: =SUMIF(원본데이터!$C$3:$C$200,A10,원본데이터!$H$3:$H$200) -> 3 | E10: =SUMIF(원본데이터!$C$3:$C$200,A10,원본데이터!$I$3:$I$200) -> 20 | F10: =IF(A10<요약!$C$4,IF(E10>0,"연체","완료"),IF(E10>0,"임박/예정","")) -> 연체
A11: 46192 | B11: =COUNTIF(원본데이터!$C$3:$C$200,A11) -> 3 | C11: =SUMIF(원본데이터!$C$3:$C$200,A11,원본데이터!$G$3:$G$200) -> 105 | D11: =SUMIF(원본데이터!$C$3:$C$200,A11,원본데이터!$H$3:$H$200) -> 105 | E11: =SUMIF(원본데이터!$C$3:$C$200,A11,원본데이터!$I$3:$I$200) -> 0 | F11: =IF(A11<요약!$C$4,IF(E11>0,"연체","완료"),IF(E11>0,"임박/예정","")) -> 완료
A12: 46193 | B12: =COUNTIF(원본데이터!$C$3:$C$200,A12) -> 2 | C12: =SUMIF(원본데이터!$C$3:$C$200,A12,원본데이터!$G$3:$G$200) -> 50 | D12: =SUMIF(원본데이터!$C$3:$C$200,A12,원본데이터!$H$3:$H$200) -> 50 | E12: =SUMIF(원본데이터!$C$3:$C$200,A12,원본데이터!$I$3:$I$200) -> 0 | F12: =IF(A12<요약!$C$4,IF(E12>0,"연체","완료"),IF(E12>0,"임박/예정","")) -> 완료
A13: 46195 | B13: =COUNTIF(원본데이터!$C$3:$C$200,A13) -> 7 | C13: =SUMIF(원본데이터!$C$3:$C$200,A13,원본데이터!$G$3:$G$200) -> 492 | D13: =SUMIF(원본데이터!$C$3:$C$200,A13,원본데이터!$H$3:$H$200) -> 492 | E13: =SUMIF(원본데이터!$C$3:$C$200,A13,원본데이터!$I$3:$I$200) -> 0 | F13: =IF(A13<요약!$C$4,IF(E13>0,"연체","완료"),IF(E13>0,"임박/예정","")) -> 완료
A14: 46198 | B14: =COUNTIF(원본데이터!$C$3:$C$200,A14) -> 5 | C14: =SUMIF(원본데이터!$C$3:$C$200,A14,원본데이터!$G$3:$G$200) -> 130 | D14: =SUMIF(원본데이터!$C$3:$C$200,A14,원본데이터!$H$3:$H$200) -> 130 | E14: =SUMIF(원본데이터!$C$3:$C$200,A14,원본데이터!$I$3:$I$200) -> 0 | F14: =IF(A14<요약!$C$4,IF(E14>0,"연체","완료"),IF(E14>0,"임박/예정","")) -> 완료
A15: 46199 | B15: =COUNTIF(원본데이터!$C$3:$C$200,A15) -> 1 | C15: =SUMIF(원본데이터!$C$3:$C$200,A15,원본데이터!$G$3:$G$200) -> 1 | D15: =SUMIF(원본데이터!$C$3:$C$200,A15,원본데이터!$H$3:$H$200) -> 1 | E15: =SUMIF(원본데이터!$C$3:$C$200,A15,원본데이터!$I$3:$I$200) -> 0 | F15: =IF(A15<요약!$C$4,IF(E15>0,"연체","완료"),IF(E15>0,"임박/예정","")) -> 완료
... A35: 46228 | B35: =COUNTIF(원본데이터!$C$3:$C$200,A35) -> 6 | C35: =SUMIF(원본데이터!$C$3:$C$200,A35,원본데이터!$G$3:$G$200) -> 109 | D35: =SUMIF(원본데이터!$C$3:$C$200,A35,원본데이터!$H$3:$H$200) -> 0 | E35: =SUMIF(원본데이터!$C$3:$C$200,A35,원본데이터!$I$3:$I$200) -> 109 | F35: =IF(A35<요약!$C$4,IF(E35>0,"연체","완료"),IF(E35>0,"임박/예정","")) -> 임박/예정

Sheet 원본데이터
A2: 수주번호 | B2: 수주일 | C2: 납기일 | D2: 거래처 | E2: 발주처 | F2: 품목명 | G2: 수주수량 | H2: 출고수량 | I2: 잔량 | J2: 상태코드 | K2: 상태명 | L2: 연체여부
A3: 2607150230 | B3: 46218 | C3: 46228 | D3: 덕원종합상사 | E3: 바른정밀 | F3: 4날/코너/4mm/초경/밑날/일반 코팅 | G3: 67 | H3: 0 | I3: =G3-H3 -> 67 | J3: SD200000 | K3: =IFERROR(INDEX({"미착수(신규접수)","진행중","부분출고","출고완료"},MATCH(J3,{"SD200000","SD200100","SD200300","SD200500"},0)),"미확인") -> 미착수(신규접수) | L3: =IF(AND(C3<요약!$C$4,I3>0),"연체","")
A4: 2607150209 | B4: 46218 | C4: 46228 | D4: 공구백화점(미산동) | F4: 재연마 | G4: 3 | H4: 0 | I4: =G4-H4 -> 3 | J4: SD200000 | K4: =IFERROR(INDEX({"미착수(신규접수)","진행중","부분출고","출고완료"},MATCH(J4,{"SD200000","SD200100","SD200300","SD200500"},0)),"미확인") -> 미착수(신규접수) | L4: =IF(AND(C4<요약!$C$4,I4>0),"연체","")
A5: 2607150190 | B5: 46218 | C5: 46228 | D5: 원영공구(구,원영상사) | E5: 에이치에스 | F5: 2날/드릴/4.3MM/HSS/밑날/비코팅 | G5: 26 | H5: 0 | I5: =G5-H5 -> 26 | J5: SD200000 | K5: =IFERROR(INDEX({"미착수(신규접수)","진행중","부분출고","출고완료"},MATCH(J5,{"SD200000","SD200100","SD200300","SD200500"},0)),"미확인") -> 미착수(신규접수) | L5: =IF(AND(C5<요약!$C$4,I5>0),"연체","")
A6: 2607150180 | B6: 46218 | C6: 46228 | D6: 원영공구(구,원영상사) | E6: 동아기계 | F6: 재연마 | G6: 1 | H6: 0 | I6: =G6-H6 -> 1 | J6: SD200000 | K6: =IFERROR(INDEX({"미착수(신규접수)","진행중","부분출고","출고완료"},MATCH(J6,{"SD200000","SD200100","SD200300","SD200500"},0)),"미확인") -> 미착수(신규접수) | L6: =IF(AND(C6<요약!$C$4,I6>0),"연체","")
A7: 2607150174 | B7: 46218 | C7: 46228 | D7: 원영공구(구,원영상사) | E7: 일월종합 | F7: 3날/평/12mm/초경/밑날/비코팅 | G7: 3 | H7: 0 | I7: =G7-H7 -> 3 | J7: SD200000 | K7: =IFERROR(INDEX({"미착수(신규접수)","진행중","부분출고","출고완료"},MATCH(J7,{"SD200000","SD200100","SD200300","SD200500"},0)),"미확인") -> 미착수(신규접수) | L7: =IF(AND(C7<요약!$C$4,I7>0),"연체","")
A8: 2607150163 | B8: 46218 | C8: 46228 | D8: 원영공구(구,원영상사) | E8: 일반 | F8: 4날/평/12mm/초경/밑날/일반 코팅 | G8: 9 | H8: 0 | I8: =G8-H8 -> 9 | J8: SD200000 | K8: =IFERROR(INDEX({"미착수(신규접수)","진행중","부분출고","출고완료"},MATCH(J8,{"SD200000","SD200100","SD200300","SD200500"},0)),"미확인") -> 미착수(신규접수) | L8: =IF(AND(C8<요약!$C$4,I8>0),"연체","")
A9: 2607130194 | B9: 46216 | C9: 46226 | D9: 아신상사 | F9: 4날/평/4mm/초경/밑날/비코팅 | G9: 144 | H9: 0 | I9: =G9-H9 -> 144 | J9: SD200000 | K9: =IFERROR(INDEX({"미착수(신규접수)","진행중","부분출고","출고완료"},MATCH(J9,{"SD200000","SD200100","SD200300","SD200500"},0)),"미확인") -> 미착수(신규접수) | L9: =IF(AND(C9<요약!$C$4,I9>0),"연체","")
A10: 2607130057 | B10: 46216 | C10: 46226 | D10: 영우툴링(창성툴) | F10: 코팅만/일반코팅/16MM이하 | G10: 5 | H10: 5 | I10: =G10-H10 -> 0 | J10: SD200500 | K10: =IFERROR(INDEX({"미착수(신규접수)","진행중","부분출고","출고완료"},MATCH(J10,{"SD200000","SD200100","SD200300","SD200500"},0)),"미확인") -> 출고완료 | L10: =IF(AND(C10<요약!$C$4,I10>0),"연체","")
A11: 2607100191 | B11: 46213 | C11: 46223 | D11: 건영테크(광주) | F11: 2날/볼/4mm/초경/밑날/일반 코팅 | G11: 79 | H11: 0 | I11: =G11-H11 -> 79 | J11: SD200000 | K11: =IFERROR(INDEX({"미착수(신규접수)","진행중","부분출고","출고완료"},MATCH(J11,{"SD200000","SD200100","SD200300","SD200500"},0)),"미확인") -> 미착수(신규접수) | L11: =IF(AND(C11<요약!$C$4,I11>0),"연체","")
A12: 2607100183 | B12: 46213 | C12: 46223 | D12: 아이티공구 | E12: 주은 | F12: 4날/평/6mm/초경/밑날/비코팅 | G12: 3 | H12: 0 | I12: =G12-H12 -> 3 | J12: SD200100 | K12: =IFERROR(INDEX({"미착수(신규접수)","진행중","부분출고","출고완료"},MATCH(J12,{"SD200000","SD200100","SD200300","SD200500"},0)),"미확인") -> 진행중 | L12: =IF(AND(C12<요약!$C$4,I12>0),"연체","")
A13: 2607100176 | B13: 46213 | C13: 46223 | D13: 동명ENG-코고툴(재연마) | F13: 2날/볼/10mm/초경/밑날/고경도 코팅 | G13: 86 | H13: 0 | I13: =G13-H13 -> 86 | J13: SD200000 | K13: =IFERROR(INDEX({"미착수(신규접수)","진행중","부분출고","출고완료"},MATCH(J13,{"SD200000","SD200100","SD200300","SD200500"},0)),"미확인") -> 미착수(신규접수) | L13: =IF(AND(C13<요약!$C$4,I13>0),"연체","")
A14: 2607100175 | B14: 46213 | C14: 46223 | D14: 반석공구 | E14: 코스맥 | F14: 4날/평/10mm/초경/밑날/일반 코팅 | G14: 6 | H14: 0 | I14: =G14-H14 -> 6 | J14: SD200000 | K14: =IFERROR(INDEX({"미착수(신규접수)","진행중","부분출고","출고완료"},MATCH(J14,{"SD200000","SD200100","SD200300","SD200500"},0)),"미확인") -> 미착수(신규접수) | L14: =IF(AND(C14<요약!$C$4,I14>0),"연체","")
A15: 2607100173 | B15: 46213 | C15: 46223 | D15: 반석공구 | E15: 삼호 | F15: 4날/평/10mm/초경/밑날/일반 코팅 | G15: 28 | H15: 0 | I15: =G15-H15 -> 28 | J15: SD200000 | K15: =IFERROR(INDEX({"미착수(신규접수)","진행중","부분출고","출고완료"},MATCH(J15,{"SD200000","SD200100","SD200300","SD200500"},0)),"미확인") -> 미착수(신규접수) | L15: =IF(AND(C15<요약!$C$4,I15>0),"연체","")
A16: 2607100170 | B16: 46213 | C16: 46223 | D16: 반석공구 | F16: 3날/평/16mm/초경/밑옆날/비코팅 | G16: 2 | H16: 0 | I16: =G16-H16 -> 2 | J16: SD200000 | K16: =IFERROR(INDEX({"미착수(신규접수)","진행중","부분출고","출고완료"},MATCH(J16,{"SD200000","SD200100","SD200300","SD200500"},0)),"미확인") -> 미착수(신규접수) | L16: =IF(AND(C16<요약!$C$4,I16>0),"연체","")
A17: 2607100148 | B17: 46213 | C17: 46223 | D17: 알제이코리아 | F17: 6날/리머/10MM/초경/밑날/비코팅 | G17: 50 | H17: 0 | I17: =G17-H17 -> 50 | J17: SD200000 | K17: =IFERROR(INDEX({"미착수(신규접수)","진행중","부분출고","출고완료"},MATCH(J17,{"SD200000","SD200100","SD200300","SD200500"},0)),"미확인") -> 미착수(신규접수) | L17: =IF(AND(C17<요약!$C$4,I17>0),"연체","")
A18: 2607100117 | B18: 46213 | C18: 46223 | D18: 대우툴링 | E18: 한테크 | F18: 2날/평/8mm/초경/밑날/일반 코팅 | G18: 10 | H18: 0 | I18: =G18-H18 -> 10 | J18: SD200000 | K18: =IFERROR(INDEX({"미착수(신규접수)","진행중","부분출고","출고완료"},MATCH(J18,{"SD200000","SD200100","SD200300","SD200500"},0)),"미확인") -> 미착수(신규접수) | L18: =IF(AND(C18<요약!$C$4,I18>0),"연체","")
A19: 2607090103 | B19: 46212 | C19: 46222 | D19: 유진상사(문래) | F19: 재연마 | G19: 1 | H19: 0 | I19: =G19-H19 -> 1 | J19: SD200000 | K19: =IFERROR(INDEX({"미착수(신규접수)","진행중","부분출고","출고완료"},MATCH(J19,{"SD200000","SD200100","SD200300","SD200500"},0)),"미확인") -> 미착수(신규접수) | L19: =IF(AND(C19<요약!$C$4,I19>0),"연체","")
A20: 2607090099 | B20: 46212 | C20: 46222 | D20: 건영테크(광주) | F20: 2날/볼/6mm/초경/밑날/일반 코팅 | G20: 119 | H20: 0 | I20: =G20-H20 -> 119 | J20: SD200000 | K20: =IFERROR(INDEX({"미착수(신규접수)","진행중","부분출고","출고완료"},MATCH(J20,{"SD200000","SD200100","SD200300","SD200500"},0)),"미확인") -> 미착수(신규접수) | L20: =IF(AND(C20<요약!$C$4,I20>0),"연체","")
A21: 2607090060 | B21: 46212 | C21: 46222 | D21: 초경툴(구,성민 | F21: 2날/볼/10mm/초경/밑날/일반 코팅 | G21: 201 | H21: 0 | I21: =G21-H21 -> 201 | J21: SD200000 | K21: =IFERROR(INDEX({"미착수(신규접수)","진행중","부분출고","출고완료"},MATCH(J21,{"SD200000","SD200100","SD200300","SD200500"},0)),"미확인") -> 미착수(신규접수) | L21: =IF(AND(C21<요약!$C$4,I21>0),"연체","")
A22: 2607080053 | B22: 46211 | C22: 46221 | D22: 덕원종합상사 | E22: JS | F22: 2날/드릴/6MM/초경/밑날/고경도코팅 | G22: 20 | H22: 5 | I22: =G22-H22 -> 15 | J22: SD200300 | K22: =IFERROR(INDEX({"미착수(신규접수)","진행중","부분출고","출고완료"},MATCH(J22,{"SD200000","SD200100","SD200300","SD200500"},0)),"미확인") -> 부분출고 | L22: =IF(AND(C22<요약!$C$4,I22>0),"연체","")
A23: 2607080050 | B23: 46211 | C23: 46221 | D23: 덕원종합상사 | E23: JS | F23: 2날/드릴/6MM/초경/밑날/고경도코팅 | G23: 18 | H23: 0 | I23: =G23-H23 -> 18 | J23: SD200000 | K23: =IFERROR(INDEX({"미착수(신규접수)","진행중","부분출고","출고완료"},MATCH(J23,{"SD200000","SD200100","SD200300","SD200500"},0)),"미확인") -> 미착수(신규접수) | L23: =IF(AND(C23<요약!$C$4,I23>0),"연체","")
A24: 2607080028 | B24: 46211 | C24: 46221 | D24: 강민툴링(비봉) | E24: 대일 | F24: 2날/드릴/19mm/초경/밑날/일반 코팅 | G24: 3 | H24: 0 | I24: =G24-H24 -> 3 | J24: SD200000 | K24: =IFERROR(INDEX({"미착수(신규접수)","진행중","부분출고","출고완료"},MATCH(J24,{"SD200000","SD200100","SD200300","SD200500"},0)),"미확인") -> 미착수(신규접수) | L24: =IF(AND(C24<요약!$C$4,I24>0),"연체","")
A25: 2607080026 | B25: 46211 | C25: 46221 | D25: 강민툴링(비봉) | E25: 서원IND | F25: 4날/평/16mm/초경/밑날/비코팅 | G25: 1 | H25: 1 | I25: =G25-H25 -> 0 | J25: SD200500 | K25: =IFERROR(INDEX({"미착수(신규접수)","진행중","부분출고","출고완료"},MATCH(J25,{"SD200000","SD200100","SD200300","SD200500"},0)),"미확인") -> 출고완료 | L25: =IF(AND(C25<요약!$C$4,I25>0),"연체","")
A26: 2607070100 | B26: 46210 | C26: 46220 | D26: 아이티공구 | E26: 유진 | F26: 재연마 | G26: 7 | H26: 0 | I26: =G26-H26 -> 7 | J26: SD200000 | K26: =IFERROR(INDEX({"미착수(신규접수)","진행중","부분출고","출고완료"},MATCH(J26,{"SD200000","SD200100","SD200300","SD200500"},0)),"미확인") -> 미착수(신규접수) | L26: =IF(AND(C26<요약!$C$4,I26>0),"연체","")
A27: 2607060074 | B27: 46209 | C27: 46219 | D27: 왕삼아공구 | F27: 4날/평/10mm/초경/밑날/일반 코팅 | G27: 10 | H27: 0 | I27: =G27-H27 -> 10 | J27: SD200000 | K27: =IFERROR(INDEX({"미착수(신규접수)","진행중","부분출고","출고완료"},MATCH(J27,{"SD200000","SD200100","SD200300","SD200500"},0)),"미확인") -> 미착수(신규접수) | L27: =IF(AND(C27<요약!$C$4,I27>0),"연체","")
A28: 2607060059 | B28: 46209 | C28: 46219 | D28: 유비툴 | E28: A | F28: 2날/드릴/3mm/초경/밑날/비코팅 | G28: 15 | H28: 0 | I28: =G28-H28 -> 15 | J28: SD200000 | K28: =IFERROR(INDEX({"미착수(신규접수)","진행중","부분출고","출고완료"},MATCH(J28,{"SD200000","SD200100","SD200300","SD200500"},0)),"미확인") -> 미착수(신규접수) | L28: =IF(AND(C28<요약!$C$4,I28>0),"연체","")
A29: 2607060057 | B29: 46209 | C29: 46219 | D29: N. | F29: 재연마 | G29: 2 | H29: 0 | I29: =G29-H29 -> 2 | J29: SD200000 | K29: =IFERROR(INDEX({"미착수(신규접수)","진행중","부분출고","출고완료"},MATCH(J29,{"SD200000","SD200100","SD200300","SD200500"},0)),"미확인") -> 미착수(신규접수) | L29: =IF(AND(C29<요약!$C$4,I29>0),"연체","")
A30: 2607030127 | B30: 46206 | C30: 46216 | D30: (주)세종종합상사(미산동) | F30: 2날/평/12mm/초경/밑날/일반 코팅 | G30: 134 | H30: 0 | I30: =G30-H30 -> 134 | J30: SD200000 | K30: =IFERROR(INDEX({"미착수(신규접수)","진행중","부분출고","출고완료"},MATCH(J30,{"SD200000","SD200100","SD200300","SD200500"},0)),"미확인") -> 미착수(신규접수) | L30: =IF(AND(C30<요약!$C$4,I30>0),"연체","") -> 연체
A31: 2607030099 | B31: 46206 | C31: 46216 | D31: 유진상사(문래) | F31: 2날/드릴/6.9mm/초경/밑날/일반 코팅 | G31: 1 | H31: 0 | I31: =G31-H31 -> 1 | J31: SD200000 | K31: =IFERROR(INDEX({"미착수(신규접수)","진행중","부분출고","출고완료"},MATCH(J31,{"SD200000","SD200100","SD200300","SD200500"},0)),"미확인") -> 미착수(신규접수) | L31: =IF(AND(C31<요약!$C$4,I31>0),"연체","") -> 연체
A32: 2607030097 | B32: 46206 | C32: 46216 | D32: (주)공화공구 | F32: 2날/코너/12mm/초경/밑날/일반 코팅 | G32: 5 | H32: 5 | I32: =G32-H32 -> 0 | J32: SD200500 | K32: =IFERROR(INDEX({"미착수(신규접수)","진행중","부분출고","출고완료"},MATCH(J32,{"SD200000","SD200100","SD200300","SD200500"},0)),"미확인") -> 출고완료 | L32: =IF(AND(C32<요약!$C$4,I32>0),"연체","")
A33: 2607020157 | B33: 46205 | C33: 46215 | D33: 영우툴링(창성툴) | E33: 에이치씨라인 | F33: 2날/볼/20mm/초경/밑날/비코팅 | G33: 6 | H33: 6 | I33: =G33-H33 -> 0 | J33: SD200500 | K33: =IFERROR(INDEX({"미착수(신규접수)","진행중","부분출고","출고완료"},MATCH(J33,{"SD200000","SD200100","SD200300","SD200500"},0)),"미확인") -> 출고완료 | L33: =IF(AND(C33<요약!$C$4,I33>0),"연체","")
A34: 2607020142 | B34: 46205 | C34: 46215 | D34: (주)금형티에스 | F34: 2날/볼/9mm/초경/밑날/일반 코팅 | G34: 9 | H34: 0 | I34: =G34-H34 -> 9 | J34: SD200000 | K34: =IFERROR(INDEX({"미착수(신규접수)","진행중","부분출고","출고완료"},MATCH(J34,{"SD200000","SD200100","SD200300","SD200500"},0)),"미확인") -> 미착수(신규접수) | L34: =IF(AND(C34<요약!$C$4,I34>0),"연체","") -> 연체
A35: 2607020137 | B35: 46205 | C35: 46215 | D35: 대륙기계공구 | F35: 2날/평/12mm/초경/밑날/비코팅 | G35: 2 | H35: 0 | I35: =G35-H35 -> 2 | J35: SD200000 | K35: =IFERROR(INDEX({"미착수(신규접수)","진행중","부분출고","출고완료"},MATCH(J35,{"SD200000","SD200100","SD200300","SD200500"},0)),"미확인") -> 미착수(신규접수) | L35: =IF(AND(C35<요약!$C$4,I35>0),"연체","") -> 연체
A36: 2607010006 | B36: 46204 | C36: 46204 | D36: (주)전진공구 | F36: 재연마 | G36: 2 | H36: 2 | I36: =G36-H36 -> 0 | J36: SD200500 | K36: =IFERROR(INDEX({"미착수(신규접수)","진행중","부분출고","출고완료"},MATCH(J36,{"SD200000","SD200100","SD200300","SD200500"},0)),"미확인") -> 출고완료 | L36: =IF(AND(C36<요약!$C$4,I36>0),"연체","")
A37: 2606300308 | B37: 46203 | C37: 46213 | D37: 반석공구 | E37: 디오프론 | F37: 3날/평/12mm/초경/밑날/비코팅 | G37: 4 | H37: 4 | I37: =G37-H37 -> 0 | J37: SD200500 | K37: =IFERROR(INDEX({"미착수(신규접수)","진행중","부분출고","출고완료"},MATCH(J37,{"SD200000","SD200100","SD200300","SD200500"},0)),"미확인") -> 출고완료 | L37: =IF(AND(C37<요약!$C$4,I37>0),"연체","")
A38: 2606300307 | B38: 46203 | C38: 46213 | D38: 아이티공구 | E38: 범양 | F38: 2날/평/20mm/HSS/밑날/일반 코팅 | G38: 12 | H38: 0 | I38: =G38-H38 -> 12 | J38: SD200100 | K38: =IFERROR(INDEX({"미착수(신규접수)","진행중","부분출고","출고완료"},MATCH(J38,{"SD200000","SD200100","SD200300","SD200500"},0)),"미확인") -> 진행중 | L38: =IF(AND(C38<요약!$C$4,I38>0),"연체","") -> 연체
A39: 2606300306 | B39: 46203 | C39: 46204 | D39: 동남종합상사(주) | F39: 4날/코너/8mm/초경/밑날/일반 코팅 | G39: 9 | H39: 0 | I39: =G39-H39 -> 9 | J39: SD200000 | K39: =IFERROR(INDEX({"미착수(신규접수)","진행중","부분출고","출고완료"},MATCH(J39,{"SD200000","SD200100","SD200300","SD200500"},0)),"미확인") -> 미착수(신규접수) | L39: =IF(AND(C39<요약!$C$4,I39>0),"연체","") -> 연체
A40: 2606300305 | B40: 46203 | C40: 46213 | D40: 원영공구(구,원영상사) | E40: HS | F40: 4날/평/6mm/초경/밑날/일반 코팅 | G40: 24 | H40: 24 | I40: =G40-H40 -> 0 | J40: SD200500 | K40: =IFERROR(INDEX({"미착수(신규접수)","진행중","부분출고","출고완료"},MATCH(J40,{"SD200000","SD200100","SD200300","SD200500"},0)),"미확인") -> 출고완료 | L40: =IF(AND(C40<요약!$C$4,I40>0),"연체","")
A41: 2606290026 | B41: 46202 | C41: 46212 | D41: 영우툴링(창성툴) | F41: 코팅만/일반코팅/35MM | G41: 1 | H41: 1 | I41: =G41-H41 -> 0 | J41: SD200500 | K41: =IFERROR(INDEX({"미착수(신규접수)","진행중","부분출고","출고완료"},MATCH(J41,{"SD200000","SD200100","SD200300","SD200500"},0)),"미확인") -> 출고완료 | L41: =IF(AND(C41<요약!$C$4,I41>0),"연체","")
...
