Workbook

Sheet 넥계산기
A1: 넥(목) 원통연삭 — iGrind 입력값 계산기 v1
A2: 노란 칸(파란 글자)만 고치세요. 나머지는 수식입니다. AI 제시 수치는 참고값 — CIM3D 시뮬레이션 → 시험 연삭 1개 → 측정 → 검증 후 양산 적용.
A4: 1. 공구 치수 입력 (mm)
A5: D — 날지름 (머리) | B5: 4 | C5: mm | D5: 카탈로그 날지름. 넥은 이 지름보다 가늘게 냄
A6: L1 — 날장 | B6: 4 | C6: mm | D6: 공구 끝(EOT)에서 날 끝까지. X Start = −(L1 + 여유)
A7: L2(블랭크) — 지금 Ø D 가 끝나는 위치 | B7: 20 | C7: mm | D7: 가공 전 공구에서 Ø D 원통이 끝나고 기존 테이퍼가 시작하는 위치. 넥을 늘리지 않으면 L2(목표)와 같게
A8: L2(목표) — 유효장 | B8: 20 | C8: mm | D8: 넥이 끝나 테이퍼에서 다시 Ø D 가 되는 위치(카탈로그 L2 정의). L2(목표) > L2(블랭크) 이면 생크를 깎는 3섹션 연장
A9: L — 전장 | B9: 50 | C9: mm | D9: 생크 남는 길이 검토용. 모르면 비워 두기
A10: S — 생크 지름 | B10: 6 | C10: mm | D10: 생크 지름. 넥 연장 시 최대 제거량·Blank OD 결정
A11: θ — 테이퍼·washout 각 (한쪽) | B11: 15 | C11: ° | D11: 기존 넥 테이퍼 각. 2JJCR 040 010 200 = 15° [제조사 기준 — 카탈로그]
A12: d — 넥 지름 (비우면 D − 여유) | C12: mm | D12: 직접 넣으면 그 값 사용. 비우면 아래 「넥 기본 여유」 적용 (decisions 2026-10-19 (6))
A13: 넥 기본 여유 (지름 기준) | B13: 0.15 | C13: mm | D13: 사내 기본 넥 = D − 0.15 [사내 경험값 — 근거 D4 1건]. D0.5 미만 미적용
A14: X Start 여유 (날장 뒤) | B14: 0.1 | C14: mm | D14: 2JJCR 기존·확정안 값 −4.1 = 날장 4 + 0.1 [사내 경험값]
A15: 홀더 물림 최소 길이 (선택) | C15: mm | D15: 넣으면 생크 남는 길이와 비교해 경고. 사내 기준 확인 필요
A17: 2. 공정 입력
A18: 황삭 1패스 반경 절입 | B18: 0.05 | C18: mm/패스 | D18: Cowork 제안 시작값 [추정값 — 시험 필요]. 이상 없으면 0.075 까지. 반경/직경 기준은 iGrind 에서 확인 필요
A19: 사내 1패스 실적 반경 절입 | B19: 0.075 | C19: mm | D19: 기존 Ø4 → Ø3.85 정삭 1패스 실적 [사내 경험값]. 이 값을 넘으면 고절입 경고
A20: 정삭 이송 (Feedrate) | B20: 2 | C20: mm/min | D20: 기존 프로그램 값 [사내 경험값, 근거 미확인]
A21: A Spin (공작물 회전) | B21: 25 | C21: rpm | D21: 기존 프로그램 값 [사내 경험값]
A22: 휠 지름 (선택) | C22: mm | D22: Pack 1 / Wheel 1 지름 미확인 — 넣으면 Vc 계산
A23: 휠 회전수 | B23: 3000 | C23: rpm | D23: 기존 프로그램 값
A25: 3. 기본 계산
A26: 적용 넥 지름 d | B26: =IF($B$12="",$B$5-$B$13,$B$12) -> 3.85 | C26: mm | D26: 식: 입력 d, 없으면 D − 여유
A27: 케이스 | B27: =IF(($B$8>$B$7),"3섹션 (넥 연장)","단일 섹션") -> 단일 섹션 | D27: 단일 = 넥 끝 washout 으로 기존 테이퍼 연결 · 3섹션 = L2(목표) > L2(블랭크), 생크를 깎음
A28: Δr — 머리 대비 반경 차 | B28: =($B$5-$B$26)/2 -> 0.075 | C28: mm | D28: 식: (D − d) ÷ 2
A29: tan θ | B29: =TAN(RADIANS($B$11)) -> 0.26794919 | D29: 15° → 0.26795
A30: Washout 길이 | B30: =$B$28/$B$29 -> 0.27990381 | C30: mm | D30: 식: Δr ÷ tan θ — 넥 끝을 θ 로 Ø D 까지 올리는 길이
A31: 넥 직선 끝 위치 (EOT 기준) | B31: =$B$8-$B$30 -> 19.720096 | C31: mm | D31: 식: L2(목표) − washout
A32: X Start (섹션 1) | B32: =-($B$6+$B$14) -> -4.1 | C32: mm | D32: 식: −(L1 + 여유)
A33: 넥 직선 길이 | B33: =$B$31-($B$6+$B$14) -> 15.620096 | C33: mm | D33: 식: 넥 직선 끝 − (L1 + 여유). iGrind 단일 섹션의 Step length 와 같음
A35: 4. iGrind Cylindrical Grinding 섹션별 입력값
A36: 섹션 | B36: 사용 | C36: X Start (mm) | D36: Step length (mm) | E36: X end (mm) | F36: Final Ø (mm) | G36: Step taper (°) | H36: Washout 각 (°) | I36: Washout 길이 (mm) | J36: Roughing | K36: Start OD | L36: Overhang
A37: S1 | B37: 사용 | C37: =$B$32 -> -4.1 | D37: =IF(($B$8>$B$7),$B$7-($B$6+$B$14),$B$31-($B$6+$B$14)) -> 15.620096 | E37: =C37-D37 -> -19.720096 | F37: =$B$26 -> 3.85 | G37: 0 | H37: =IF(($B$8>$B$7),0,$B$11) -> 15 | I37: =IF(($B$8>$B$7),0,$B$30) -> 0.27990381 | J37: =IF($B$28>$B$19,"켬 (Δr > 실적 — 분할)","끔 (정삭 1패스)") -> 끔 (정삭 1패스) | K37: =IF(($B$8>$B$7),"Define "&TEXT($B$5,"0.0##"),"Blank (Ø D)") -> Blank (Ø D) | L37: 끔
A38: S2 | B38: =IF(($B$8>$B$7),"사용","— (없음)") -> — (없음) | C38: =IF(($B$8>$B$7),-$B$7,"—") -> — | D38: =IF(($B$8>$B$7),$B$31-$B$7,"—") -> — | E38: =IF(($B$8>$B$7),C38-D38,"—") -> — | F38: =IF(($B$8>$B$7),$B$26,"—") -> — | G38: =IF(($B$8>$B$7),0,"—") -> — | H38: =IF(($B$8>$B$7),0,"—") -> — | I38: =IF(($B$8>$B$7),0,"—") -> — | J38: =IF(($B$8>$B$7),"켬","—") -> — | K38: =IF(($B$8>$B$7),"Define "&TEXT(MIN($B$10,$B$5+2*($B$31-$B$7)*$B$29),"0.0##"),"—") -> — | L38: =IF(($B$8>$B$7),"끔","—") -> —
A39: S3 | B39: =IF(($B$8>$B$7),"사용","— (없음)") -> — (없음) | C39: =IF(($B$8>$B$7),-$B$31,"—") -> — | D39: =IF(($B$8>$B$7),($B$10-$B$26)/(2*$B$29),"—") -> — | E39: =IF(($B$8>$B$7),C39-D39,"—") -> — | F39: =IF(($B$8>$B$7),$B$26,"—") -> — | G39: =IF(($B$8>$B$7),$B$11,"—") -> — | H39: =IF(($B$8>$B$7),0,"—") -> — | I39: =IF(($B$8>$B$7),0,"—") -> — | J39: =IF(($B$8>$B$7),"켬","—") -> — | K39: =IF(($B$8>$B$7),"Define "&TEXT($B$10,"0.0##"),"—") -> — | L39: =IF(($B$8>$B$7),"끔","—") -> —
A40: · S3 Final Ø 는 EOT 쪽 끝 지름(테이퍼 시작). Step taper 15° 가 한쪽/양쪽 기준인지, 부호 방향은 iGrind 2D 탭에서 S3 끝이 Ø S 로 그려지는지로 확인 [확인 필요]
A41: · 단일 섹션: 다른 섹션은 지우거나 X Start 체인 링크를 끊고 정리. Step length 는 washout 제외 [제조사 기준 — iGrind Grinding Manual §30.9]
A43: 5. 검토 지표
A44: 최대 반경 제거량 | B44: =IF(($B$8>$B$7),(MIN($B$10,$B$5+2*($B$31-$B$7)*$B$29)-$B$26)/2,$B$28) -> 0.075 | C44: mm | D44: 연장: (그 위치 블랭크 지름 − d) ÷ 2 / 단일: Δr
A45: S2 블랭크 최대 지름 (Start OD) | B45: =IF(($B$8>$B$7),MIN($B$10,$B$5+2*($B$31-$B$7)*$B$29),"—") -> — | C45: mm | D45: 식: MIN(S, D + 2 × (넥 직선 끝 − L2(블랭크)) × tan θ)
...

Sheet 가능성비교
A1: 가능성 비교 — 한 줄에 한 안(案)
A2: 노란 칸 입력 → 오른쪽 결과. 넥 기본 여유·X Start 여유·황삭 절입·실적 절입·이송은 「넥계산기」 시트 값을 공통으로 씀(초록 글자). d 를 비우면 D − 여유. 예시 줄 3~5는 L2 만 바꾼 가정값(가능성 비교용) — 실제 품번 아님.
A3: 공통값 → | B3: 넥 여유 | D3: =넥계산기!$B$13 -> 0.15 | E3: X Start 여유 | G3: =넥계산기!$B$14 -> 0.1 | H3: 황삭 절입 | J3: =넥계산기!$B$18 -> 0.05 | K3: 실적 절입 | M3: =넥계산기!$B$19 -> 0.075 | N3: 이송 | P3: =넥계산기!$B$20 -> 2
A5: 구분 / 메모 | B5: D | C5: L1 날장 | D5: L2(블랭크) | E5: L2(목표) | F5: L 전장 | G5: S 생크 | H5: θ (°) | I5: d 입력 | J5: 적용 d | K5: 케이스 | L5: Washout 길이 | M5: X Start | N5: S1 Step length | O5: S2 Step length | P5: S3 Step length | Q5: 넥 직선 끝 X | R5: S2 Start OD | S5: 최대 반경 제거 | T5: 황삭 패스 | U5: 강성 비 | V5: 처짐 배율 | W5: L2÷D | X5: 적용 구분 | Y5: 생크 남는 길이 | Z5: 정삭 1패스 (분)
A6: 2JJCR 040 010 200 (카탈로그 치수 · 넥 Ø3.85 확정안) | B6: 4 | C6: 4 | D6: 20 | E6: 20 | F6: 50 | G6: 6 | H6: 15 | J6: =IF(B6="","",IF(I6="",B6-넥계산기!$B$13,I6)) -> 3.85 | K6: =IF(B6="","",IF((E6>D6),"3섹션 연장","단일")) -> 단일 | L6: =IF(B6="","",((B6-J6)/2)/TAN(RADIANS(H6))) -> 0.27990381 | M6: =IF(B6="","",-(C6+넥계산기!$B$14)) -> -4.1 | N6: =IF(B6="","",IF((E6>D6),D6-(C6+넥계산기!$B$14),Q6-(C6+넥계산기!$B$14))) -> 15.620096 | O6: =IF(B6="","",IF((E6>D6),Q6-D6,"—")) -> — | P6: =IF(B6="","",IF((E6>D6),(G6-J6)/(2*TAN(RADIANS(H6))),"—")) -> — | Q6: =IF(B6="","",E6-L6) -> 19.720096 | R6: =IF(B6="","",IF((E6>D6),MIN(G6,B6+2*(Q6-D6)*TAN(RADIANS(H6))),"—")) -> — | S6: =IF(B6="","",IF((E6>D6),(MIN(G6,B6+2*(Q6-D6)*TAN(RADIANS(H6)))-J6)/2,((B6-J6)/2))) -> 0.075 | T6: =IF(B6="","",IF((E6>D6),ROUNDUP(S6/넥계산기!$B$18,0),IF(((B6-J6)/2)>넥계산기!$B$19,ROUNDUP(((B6-J6)/2)/넥계산기!$B$18,0),1))) -> 1 | U6: =IF(B6="","",(J6/B6)^4) -> 0.85822854 | V6: =IF(B6="","",1/U6) -> 1.1651908 | W6: =IF(B6="","",E6/B6) -> 5 | X6: =IF(B6="","",IF(B6<0.5,"⛔ 미적용",IF(B6<2,"🔴 개별 확인",IF(B6<2.5,"🟡 개별(유효장 길면)",IF(B6<8,"🟢 기본 적용","🟡 여유 확인"))))) -> 🟢 기본 적용 | Y6: =IF(B6="","",IF(F6="","전장 입력",F6-IF((E6>D6),Q6+P6,D6+(G6-B6)/(2*TAN(RADIANS(H6)))))) -> 26.267949 | Z6: =IF(B6="","",IF((E6>D6),(N6+O6+P6)/넥계산기!$B$20,(N6+L6)/넥계산기!$B$20)) -> 7.95
A7: 테스트 D4 2날 평 L2 8 → 14 (10-19, 전장 미입력) | B7: 4 | C7: 4 | D7: 8 | E7: 14 | G7: 6 | H7: 15 | J7: =IF(B7="","",IF(I7="",B7-넥계산기!$B$13,I7)) -> 3.85 | K7: =IF(B7="","",IF((E7>D7),"3섹션 연장","단일")) -> 3섹션 연장 | L7: =IF(B7="","",((B7-J7)/2)/TAN(RADIANS(H7))) -> 0.27990381 | M7: =IF(B7="","",-(C7+넥계산기!$B$14)) -> -4.1 | N7: =IF(B7="","",IF((E7>D7),D7-(C7+넥계산기!$B$14),Q7-(C7+넥계산기!$B$14))) -> 3.9 | O7: =IF(B7="","",IF((E7>D7),Q7-D7,"—")) -> 5.7200962 | P7: =IF(B7="","",IF((E7>D7),(G7-J7)/(2*TAN(RADIANS(H7))),"—")) -> 4.0119546 | Q7: =IF(B7="","",E7-L7) -> 13.720096 | R7: =IF(B7="","",IF((E7>D7),MIN(G7,B7+2*(Q7-D7)*TAN(RADIANS(H7))),"—")) -> 6 | S7: =IF(B7="","",IF((E7>D7),(MIN(G7,B7+2*(Q7-D7)*TAN(RADIANS(H7)))-J7)/2,((B7-J7)/2))) -> 1.075 | T7: =IF(B7="","",IF((E7>D7),ROUNDUP(S7/넥계산기!$B$18,0),IF(((B7-J7)/2)>넥계산기!$B$19,ROUNDUP(((B7-J7)/2)/넥계산기!$B$18,0),1))) -> 22 | U7: =IF(B7="","",(J7/B7)^4) -> 0.85822854 | V7: =IF(B7="","",1/U7) -> 1.1651908 | W7: =IF(B7="","",E7/B7) -> 3.5 | X7: =IF(B7="","",IF(B7<0.5,"⛔ 미적용",IF(B7<2,"🔴 개별 확인",IF(B7<2.5,"🟡 개별(유효장 길면)",IF(B7<8,"🟢 기본 적용","🟡 여유 확인"))))) -> 🟢 기본 적용 | Y7: =IF(B7="","",IF(F7="","전장 입력",F7-IF((E7>D7),Q7+P7,D7+(G7-B7)/(2*TAN(RADIANS(H7)))))) -> 전장 입력 | Z7: =IF(B7="","",IF((E7>D7),(N7+O7+P7)/넥계산기!$B$20,(N7+L7)/넥계산기!$B$20)) -> 6.8160254
A8: 예시 — D4 L2 8 → 12 (가정값) | B8: 4 | C8: 4 | D8: 8 | E8: 12 | F8: 50 | G8: 6 | H8: 15 | J8: =IF(B8="","",IF(I8="",B8-넥계산기!$B$13,I8)) -> 3.85 | K8: =IF(B8="","",IF((E8>D8),"3섹션 연장","단일")) -> 3섹션 연장 | L8: =IF(B8="","",((B8-J8)/2)/TAN(RADIANS(H8))) -> 0.27990381 | M8: =IF(B8="","",-(C8+넥계산기!$B$14)) -> -4.1 | N8: =IF(B8="","",IF((E8>D8),D8-(C8+넥계산기!$B$14),Q8-(C8+넥계산기!$B$14))) -> 3.9 | O8: =IF(B8="","",IF((E8>D8),Q8-D8,"—")) -> 3.7200962 | P8: =IF(B8="","",IF((E8>D8),(G8-J8)/(2*TAN(RADIANS(H8))),"—")) -> 4.0119546 | Q8: =IF(B8="","",E8-L8) -> 11.720096 | R8: =IF(B8="","",IF((E8>D8),MIN(G8,B8+2*(Q8-D8)*TAN(RADIANS(H8))),"—")) -> 5.9935935 | S8: =IF(B8="","",IF((E8>D8),(MIN(G8,B8+2*(Q8-D8)*TAN(RADIANS(H8)))-J8)/2,((B8-J8)/2))) -> 1.0717968 | T8: =IF(B8="","",IF((E8>D8),ROUNDUP(S8/넥계산기!$B$18,0),IF(((B8-J8)/2)>넥계산기!$B$19,ROUNDUP(((B8-J8)/2)/넥계산기!$B$18,0),1))) -> 22 | U8: =IF(B8="","",(J8/B8)^4) -> 0.85822854 | V8: =IF(B8="","",1/U8) -> 1.1651908 | W8: =IF(B8="","",E8/B8) -> 3 | X8: =IF(B8="","",IF(B8<0.5,"⛔ 미적용",IF(B8<2,"🔴 개별 확인",IF(B8<2.5,"🟡 개별(유효장 길면)",IF(B8<8,"🟢 기본 적용","🟡 여유 확인"))))) -> 🟢 기본 적용 | Y8: =IF(B8="","",IF(F8="","전장 입력",F8-IF((E8>D8),Q8+P8,D8+(G8-B8)/(2*TAN(RADIANS(H8)))))) -> 34.267949 | Z8: =IF(B8="","",IF((E8>D8),(N8+O8+P8)/넥계산기!$B$20,(N8+L8)/넥계산기!$B$20)) -> 5.8160254
A9: 예시 — D4 L2 8 → 16 (가정값) | B9: 4 | C9: 4 | D9: 8 | E9: 16 | F9: 50 | G9: 6 | H9: 15 | J9: =IF(B9="","",IF(I9="",B9-넥계산기!$B$13,I9)) -> 3.85 | K9: =IF(B9="","",IF((E9>D9),"3섹션 연장","단일")) -> 3섹션 연장 | L9: =IF(B9="","",((B9-J9)/2)/TAN(RADIANS(H9))) -> 0.27990381 | M9: =IF(B9="","",-(C9+넥계산기!$B$14)) -> -4.1 | N9: =IF(B9="","",IF((E9>D9),D9-(C9+넥계산기!$B$14),Q9-(C9+넥계산기!$B$14))) -> 3.9 | O9: =IF(B9="","",IF((E9>D9),Q9-D9,"—")) -> 7.7200962 | P9: =IF(B9="","",IF((E9>D9),(G9-J9)/(2*TAN(RADIANS(H9))),"—")) -> 4.0119546 | Q9: =IF(B9="","",E9-L9) -> 15.720096 | R9: =IF(B9="","",IF((E9>D9),MIN(G9,B9+2*(Q9-D9)*TAN(RADIANS(H9))),"—")) -> 6 | S9: =IF(B9="","",IF((E9>D9),(MIN(G9,B9+2*(Q9-D9)*TAN(RADIANS(H9)))-J9)/2,((B9-J9)/2))) -> 1.075 | T9: =IF(B9="","",IF((E9>D9),ROUNDUP(S9/넥계산기!$B$18,0),IF(((B9-J9)/2)>넥계산기!$B$19,ROUNDUP(((B9-J9)/2)/넥계산기!$B$18,0),1))) -> 22 | U9: =IF(B9="","",(J9/B9)^4) -> 0.85822854 | V9: =IF(B9="","",1/U9) -> 1.1651908 | W9: =IF(B9="","",E9/B9) -> 4 | X9: =IF(B9="","",IF(B9<0.5,"⛔ 미적용",IF(B9<2,"🔴 개별 확인",IF(B9<2.5,"🟡 개별(유효장 길면)",IF(B9<8,"🟢 기본 적용","🟡 여유 확인"))))) -> 🟢 기본 적용 | Y9: =IF(B9="","",IF(F9="","전장 입력",F9-IF((E9>D9),Q9+P9,D9+(G9-B9)/(2*TAN(RADIANS(H9)))))) -> 30.267949 | Z9: =IF(B9="","",IF((E9>D9),(N9+O9+P9)/넥계산기!$B$20,(N9+L9)/넥계산기!$B$20)) -> 7.8160254
A10: 예시 — D4 L2 8 → 20 (가정값) | B10: 4 | C10: 4 | D10: 8 | E10: 20 | F10: 50 | G10: 6 | H10: 15 | J10: =IF(B10="","",IF(I10="",B10-넥계산기!$B$13,I10)) -> 3.85 | K10: =IF(B10="","",IF((E10>D10),"3섹션 연장","단일")) -> 3섹션 연장 | L10: =IF(B10="","",((B10-J10)/2)/TAN(RADIANS(H10))) -> 0.27990381 | M10: =IF(B10="","",-(C10+넥계산기!$B$14)) -> -4.1 | N10: =IF(B10="","",IF((E10>D10),D10-(C10+넥계산기!$B$14),Q10-(C10+넥계산기!$B$14))) -> 3.9 | O10: =IF(B10="","",IF((E10>D10),Q10-D10,"—")) -> 11.720096 | P10: =IF(B10="","",IF((E10>D10),(G10-J10)/(2*TAN(RADIANS(H10))),"—")) -> 4.0119546 | Q10: =IF(B10="","",E10-L10) -> 19.720096 | R10: =IF(B10="","",IF((E10>D10),MIN(G10,B10+2*(Q10-D10)*TAN(RADIANS(H10))),"—")) -> 6 | S10: =IF(B10="","",IF((E10>D10),(MIN(G10,B10+2*(Q10-D10)*TAN(RADIANS(H10)))-J10)/2,((B10-J10)/2))) -> 1.075 | T10: =IF(B10="","",IF((E10>D10),ROUNDUP(S10/넥계산기!$B$18,0),IF(((B10-J10)/2)>넥계산기!$B$19,ROUNDUP(((B10-J10)/2)/넥계산기!$B$18,0),1))) -> 22 | U10: =IF(B10="","",(J10/B10)^4) -> 0.85822854 | V10: =IF(B10="","",1/U10) -> 1.1651908 | W10: =IF(B10="","",E10/B10) -> 5 | X10: =IF(B10="","",IF(B10<0.5,"⛔ 미적용",IF(B10<2,"🔴 개별 확인",IF(B10<2.5,"🟡 개별(유효장 길면)",IF(B10<8,"🟢 기본 적용","🟡 여유 확인"))))) -> 🟢 기본 적용 | Y10: =IF(B10="","",IF(F10="","전장 입력",F10-IF((E10>D10),Q10+P10,D10+(G10-B10)/(2*TAN(RADIANS(H10)))))) -> 26.267949 | Z10: =IF(B10="","",IF((E10>D10),(N10+O10+P10)/넥계산기!$B$20,(N10+L10)/넥계산기!$B$20)) -> 9.8160254
J11: =IF(B11="","",IF(I11="",B11-넥계산기!$B$13,I11)) | K11: =IF(B11="","",IF((E11>D11),"3섹션 연장","단일")) | L11: =IF(B11="","",((B11-J11)/2)/TAN(RADIANS(H11))) | M11: =IF(B11="","",-(C11+넥계산기!$B$14)) | N11: =IF(B11="","",IF((E11>D11),D11-(C11+넥계산기!$B$14),Q11-(C11+넥계산기!$B$14))) | O11: =IF(B11="","",IF((E11>D11),Q11-D11,"—")) | P11: =IF(B11="","",IF((E11>D11),(G11-J11)/(2*TAN(RADIANS(H11))),"—")) | Q11: =IF(B11="","",E11-L11) | R11: =IF(B11="","",IF((E11>D11),MIN(G11,B11+2*(Q11-D11)*TAN(RADIANS(H11))),"—")) | S11: =IF(B11="","",IF((E11>D11),(MIN(G11,B11+2*(Q11-D11)*TAN(RADIANS(H11)))-J11)/2,((B11-J11)/2))) | T11: =IF(B11="","",IF((E11>D11),ROUNDUP(S11/넥계산기!$B$18,0),IF(((B11-J11)/2)>넥계산기!$B$19,ROUNDUP(((B11-J11)/2)/넥계산기!$B$18,0),1))) | U11: =IF(B11="","",(J11/B11)^4) | V11: =IF(B11="","",1/U11) | W11: =IF(B11="","",E11/B11) | X11: =IF(B11="","",IF(B11<0.5,"⛔ 미적용",IF(B11<2,"🔴 개별 확인",IF(B11<2.5,"🟡 개별(유효장 길면)",IF(B11<8,"🟢 기본 적용","🟡 여유 확인"))))) | Y11: =IF(B11="","",IF(F11="","전장 입력",F11-IF((E11>D11),Q11+P11,D11+(G11-B11)/(2*TAN(RADIANS(H11)))))) | Z11: =IF(B11="","",IF((E11>D11),(N11+O11+P11)/넥계산기!$B$20,(N11+L11)/넥계산기!$B$20))
J12: =IF(B12="","",IF(I12="",B12-넥계산기!$B$13,I12)) | K12: =IF(B12="","",IF((E12>D12),"3섹션 연장","단일")) | L12: =IF(B12="","",((B12-J12)/2)/TAN(RADIANS(H12))) | M12: =IF(B12="","",-(C12+넥계산기!$B$14)) | N12: =IF(B12="","",IF((E12>D12),D12-(C12+넥계산기!$B$14),Q12-(C12+넥계산기!$B$14))) | O12: =IF(B12="","",IF((E12>D12),Q12-D12,"—")) | P12: =IF(B12="","",IF((E12>D12),(G12-J12)/(2*TAN(RADIANS(H12))),"—")) | Q12: =IF(B12="","",E12-L12) | R12: =IF(B12="","",IF((E12>D12),MIN(G12,B12+2*(Q12-D12)*TAN(RADIANS(H12))),"—")) | S12: =IF(B12="","",IF((E12>D12),(MIN(G12,B12+2*(Q12-D12)*TAN(RADIANS(H12)))-J12)/2,((B12-J12)/2))) | T12: =IF(B12="","",IF((E12>D12),ROUNDUP(S12/넥계산기!$B$18,0),IF(((B12-J12)/2)>넥계산기!$B$19,ROUNDUP(((B12-J12)/2)/넥계산기!$B$18,0),1))) | U12: =IF(B12="","",(J12/B12)^4) | V12: =IF(B12="","",1/U12) | W12: =IF(B12="","",E12/B12) | X12: =IF(B12="","",IF(B12<0.5,"⛔ 미적용",IF(B12<2,"🔴 개별 확인",IF(B12<2.5,"🟡 개별(유효장 길면)",IF(B12<8,"🟢 기본 적용","🟡 여유 확인"))))) | Y12: =IF(B12="","",IF(F12="","전장 입력",F12-IF((E12>D12),Q12+P12,D12+(G12-B12)/(2*TAN(RADIANS(H12)))))) | Z12: =IF(B12="","",IF((E12>D12),(N12+O12+P12)/넥계산기!$B$20,(N12+L12)/넥계산기!$B$20))
J13: =IF(B13="","",IF(I13="",B13-넥계산기!$B$13,I13)) | K13: =IF(B13="","",IF((E13>D13),"3섹션 연장","단일")) | L13: =IF(B13="","",((B13-J13)/2)/TAN(RADIANS(H13))) | M13: =IF(B13="","",-(C13+넥계산기!$B$14)) | N13: =IF(B13="","",IF((E13>D13),D13-(C13+넥계산기!$B$14),Q13-(C13+넥계산기!$B$14))) | O13: =IF(B13="","",IF((E13>D13),Q13-D13,"—")) | P13: =IF(B13="","",IF((E13>D13),(G13-J13)/(2*TAN(RADIANS(H13))),"—")) | Q13: =IF(B13="","",E13-L13) | R13: =IF(B13="","",IF((E13>D13),MIN(G13,B13+2*(Q13-D13)*TAN(RADIANS(H13))),"—")) | S13: =IF(B13="","",IF((E13>D13),(MIN(G13,B13+2*(Q13-D13)*TAN(RADIANS(H13)))-J13)/2,((B13-J13)/2))) | T13: =IF(B13="","",IF((E13>D13),ROUNDUP(S13/넥계산기!$B$18,0),IF(((B13-J13)/2)>넥계산기!$B$19,ROUNDUP(((B13-J13)/2)/넥계산기!$B$18,0),1))) | U13: =IF(B13="","",(J13/B13)^4) | V13: =IF(B13="","",1/U13) | W13: =IF(B13="","",E13/B13) | X13: =IF(B13="","",IF(B13<0.5,"⛔ 미적용",IF(B13<2,"🔴 개별 확인",IF(B13<2.5,"🟡 개별(유효장 길면)",IF(B13<8,"🟢 기본 적용","🟡 여유 확인"))))) | Y13: =IF(B13="","",IF(F13="","전장 입력",F13-IF((E13>D13),Q13+P13,D13+(G13-B13)/(2*TAN(RADIANS(H13)))))) | Z13: =IF(B13="","",IF((E13>D13),(N13+O13+P13)/넥계산기!$B$20,(N13+L13)/넥계산기!$B$20))
J14: =IF(B14="","",IF(I14="",B14-넥계산기!$B$13,I14)) | K14: =IF(B14="","",IF((E14>D14),"3섹션 연장","단일")) | L14: =IF(B14="","",((B14-J14)/2)/TAN(RADIANS(H14))) | M14: =IF(B14="","",-(C14+넥계산기!$B$14)) | N14: =IF(B14="","",IF((E14>D14),D14-(C14+넥계산기!$B$14),Q14-(C14+넥계산기!$B$14))) | O14: =IF(B14="","",IF((E14>D14),Q14-D14,"—")) | P14: =IF(B14="","",IF((E14>D14),(G14-J14)/(2*TAN(RADIANS(H14))),"—")) | Q14: =IF(B14="","",E14-L14) | R14: =IF(B14="","",IF((E14>D14),MIN(G14,B14+2*(Q14-D14)*TAN(RADIANS(H14))),"—")) | S14: =IF(B14="","",IF((E14>D14),(MIN(G14,B14+2*(Q14-D14)*TAN(RADIANS(H14)))-J14)/2,((B14-J14)/2))) | T14: =IF(B14="","",IF((E14>D14),ROUNDUP(S14/넥계산기!$B$18,0),IF(((B14-J14)/2)>넥계산기!$B$19,ROUNDUP(((B14-J14)/2)/넥계산기!$B$18,0),1))) | U14: =IF(B14="","",(J14/B14)^4) | V14: =IF(B14="","",1/U14) | W14: =IF(B14="","",E14/B14) | X14: =IF(B14="","",IF(B14<0.5,"⛔ 미적용",IF(B14<2,"🔴 개별 확인",IF(B14<2.5,"🟡 개별(유효장 길면)",IF(B14<8,"🟢 기본 적용","🟡 여유 확인"))))) | Y14: =IF(B14="","",IF(F14="","전장 입력",F14-IF((E14>D14),Q14+P14,D14+(G14-B14)/(2*TAN(RADIANS(H14)))))) | Z14: =IF(B14="","",IF((E14>D14),(N14+O14+P14)/넥계산기!$B$20,(N14+L14)/넥계산기!$B$20))
J15: =IF(B15="","",IF(I15="",B15-넥계산기!$B$13,I15)) | K15: =IF(B15="","",IF((E15>D15),"3섹션 연장","단일")) | L15: =IF(B15="","",((B15-J15)/2)/TAN(RADIANS(H15))) | M15: =IF(B15="","",-(C15+넥계산기!$B$14)) | N15: =IF(B15="","",IF((E15>D15),D15-(C15+넥계산기!$B$14),Q15-(C15+넥계산기!$B$14))) | O15: =IF(B15="","",IF((E15>D15),Q15-D15,"—")) | P15: =IF(B15="","",IF((E15>D15),(G15-J15)/(2*TAN(RADIANS(H15))),"—")) | Q15: =IF(B15="","",E15-L15) | R15: =IF(B15="","",IF((E15>D15),MIN(G15,B15+2*(Q15-D15)*TAN(RADIANS(H15))),"—")) | S15: =IF(B15="","",IF((E15>D15),(MIN(G15,B15+2*(Q15-D15)*TAN(RADIANS(H15)))-J15)/2,((B15-J15)/2))) | T15: =IF(B15="","",IF((E15>D15),ROUNDUP(S15/넥계산기!$B$18,0),IF(((B15-J15)/2)>넥계산기!$B$19,ROUNDUP(((B15-J15)/2)/넥계산기!$B$18,0),1))) | U15: =IF(B15="","",(J15/B15)^4) | V15: =IF(B15="","",1/U15) | W15: =IF(B15="","",E15/B15) | X15: =IF(B15="","",IF(B15<0.5,"⛔ 미적용",IF(B15<2,"🔴 개별 확인",IF(B15<2.5,"🟡 개별(유효장 길면)",IF(B15<8,"🟢 기본 적용","🟡 여유 확인"))))) | Y15: =IF(B15="","",IF(F15="","전장 입력",F15-IF((E15>D15),Q15+P15,D15+(G15-B15)/(2*TAN(RADIANS(H15)))))) | Z15: =IF(B15="","",IF((E15>D15),(N15+O15+P15)/넥계산기!$B$20,(N15+L15)/넥계산기!$B$20))
J16: =IF(B16="","",IF(I16="",B16-넥계산기!$B$13,I16)) | K16: =IF(B16="","",IF((E16>D16),"3섹션 연장","단일")) | L16: =IF(B16="","",((B16-J16)/2)/TAN(RADIANS(H16))) | M16: =IF(B16="","",-(C16+넥계산기!$B$14)) | N16: =IF(B16="","",IF((E16>D16),D16-(C16+넥계산기!$B$14),Q16-(C16+넥계산기!$B$14))) | O16: =IF(B16="","",IF((E16>D16),Q16-D16,"—")) | P16: =IF(B16="","",IF((E16>D16),(G16-J16)/(2*TAN(RADIANS(H16))),"—")) | Q16: =IF(B16="","",E16-L16) | R16: =IF(B16="","",IF((E16>D16),MIN(G16,B16+2*(Q16-D16)*TAN(RADIANS(H16))),"—")) | S16: =IF(B16="","",IF((E16>D16),(MIN(G16,B16+2*(Q16-D16)*TAN(RADIANS(H16)))-J16)/2,((B16-J16)/2))) | T16: =IF(B16="","",IF((E16>D16),ROUNDUP(S16/넥계산기!$B$18,0),IF(((B16-J16)/2)>넥계산기!$B$19,ROUNDUP(((B16-J16)/2)/넥계산기!$B$18,0),1))) | U16: =IF(B16="","",(J16/B16)^4) | V16: =IF(B16="","",1/U16) | W16: =IF(B16="","",E16/B16) | X16: =IF(B16="","",IF(B16<0.5,"⛔ 미적용",IF(B16<2,"🔴 개별 확인",IF(B16<2.5,"🟡 개별(유효장 길면)",IF(B16<8,"🟢 기본 적용","🟡 여유 확인"))))) | Y16: =IF(B16="","",IF(F16="","전장 입력",F16-IF((E16>D16),Q16+P16,D16+(G16-B16)/(2*TAN(RADIANS(H16)))))) | Z16: =IF(B16="","",IF((E16>D16),(N16+O16+P16)/넥계산기!$B$20,(N16+L16)/넥계산기!$B$20))
J17: =IF(B17="","",IF(I17="",B17-넥계산기!$B$13,I17)) | K17: =IF(B17="","",IF((E17>D17),"3섹션 연장","단일")) | L17: =IF(B17="","",((B17-J17)/2)/TAN(RADIANS(H17))) | M17: =IF(B17="","",-(C17+넥계산기!$B$14)) | N17: =IF(B17="","",IF((E17>D17),D17-(C17+넥계산기!$B$14),Q17-(C17+넥계산기!$B$14))) | O17: =IF(B17="","",IF((E17>D17),Q17-D17,"—")) | P17: =IF(B17="","",IF((E17>D17),(G17-J17)/(2*TAN(RADIANS(H17))),"—")) | Q17: =IF(B17="","",E17-L17) | R17: =IF(B17="","",IF((E17>D17),MIN(G17,B17+2*(Q17-D17)*TAN(RADIANS(H17))),"—")) | S17: =IF(B17="","",IF((E17>D17),(MIN(G17,B17+2*(Q17-D17)*TAN(RADIANS(H17)))-J17)/2,((B17-J17)/2))) | T17: =IF(B17="","",IF((E17>D17),ROUNDUP(S17/넥계산기!$B$18,0),IF(((B17-J17)/2)>넥계산기!$B$19,ROUNDUP(((B17-J17)/2)/넥계산기!$B$18,0),1))) | U17: =IF(B17="","",(J17/B17)^4) | V17: =IF(B17="","",1/U17) | W17: =IF(B17="","",E17/B17) | X17: =IF(B17="","",IF(B17<0.5,"⛔ 미적용",IF(B17<2,"🔴 개별 확인",IF(B17<2.5,"🟡 개별(유효장 길면)",IF(B17<8,"🟢 기본 적용","🟡 여유 확인"))))) | Y17: =IF(B17="","",IF(F17="","전장 입력",F17-IF((E17>D17),Q17+P17,D17+(G17-B17)/(2*TAN(RADIANS(H17)))))) | Z17: =IF(B17="","",IF((E17>D17),(N17+O17+P17)/넥계산기!$B$20,(N17+L17)/넥계산기!$B$20))
J18: =IF(B18="","",IF(I18="",B18-넥계산기!$B$13,I18)) | K18: =IF(B18="","",IF((E18>D18),"3섹션 연장","단일")) | L18: =IF(B18="","",((B18-J18)/2)/TAN(RADIANS(H18))) | M18: =IF(B18="","",-(C18+넥계산기!$B$14)) | N18: =IF(B18="","",IF((E18>D18),D18-(C18+넥계산기!$B$14),Q18-(C18+넥계산기!$B$14))) | O18: =IF(B18="","",IF((E18>D18),Q18-D18,"—")) | P18: =IF(B18="","",IF((E18>D18),(G18-J18)/(2*TAN(RADIANS(H18))),"—")) | Q18: =IF(B18="","",E18-L18) | R18: =IF(B18="","",IF((E18>D18),MIN(G18,B18+2*(Q18-D18)*TAN(RADIANS(H18))),"—")) | S18: =IF(B18="","",IF((E18>D18),(MIN(G18,B18+2*(Q18-D18)*TAN(RADIANS(H18)))-J18)/2,((B18-J18)/2))) | T18: =IF(B18="","",IF((E18>D18),ROUNDUP(S18/넥계산기!$B$18,0),IF(((B18-J18)/2)>넥계산기!$B$19,ROUNDUP(((B18-J18)/2)/넥계산기!$B$18,0),1))) | U18: =IF(B18="","",(J18/B18)^4) | V18: =IF(B18="","",1/U18) | W18: =IF(B18="","",E18/B18) | X18: =IF(B18="","",IF(B18<0.5,"⛔ 미적용",IF(B18<2,"🔴 개별 확인",IF(B18<2.5,"🟡 개별(유효장 길면)",IF(B18<8,"🟢 기본 적용","🟡 여유 확인"))))) | Y18: =IF(B18="","",IF(F18="","전장 입력",F18-IF((E18>D18),Q18+P18,D18+(G18-B18)/(2*TAN(RADIANS(H18)))))) | Z18: =IF(B18="","",IF((E18>D18),(N18+O18+P18)/넥계산기!$B$20,(N18+L18)/넥계산기!$B$20))
J19: =IF(B19="","",IF(I19="",B19-넥계산기!$B$13,I19)) | K19: =IF(B19="","",IF((E19>D19),"3섹션 연장","단일")) | L19: =IF(B19="","",((B19-J19)/2)/TAN(RADIANS(H19))) | M19: =IF(B19="","",-(C19+넥계산기!$B$14)) | N19: =IF(B19="","",IF((E19>D19),D19-(C19+넥계산기!$B$14),Q19-(C19+넥계산기!$B$14))) | O19: =IF(B19="","",IF((E19>D19),Q19-D19,"—")) | P19: =IF(B19="","",IF((E19>D19),(G19-J19)/(2*TAN(RADIANS(H19))),"—")) | Q19: =IF(B19="","",E19-L19) | R19: =IF(B19="","",IF((E19>D19),MIN(G19,B19+2*(Q19-D19)*TAN(RADIANS(H19))),"—")) | S19: =IF(B19="","",IF((E19>D19),(MIN(G19,B19+2*(Q19-D19)*TAN(RADIANS(H19)))-J19)/2,((B19-J19)/2))) | T19: =IF(B19="","",IF((E19>D19),ROUNDUP(S19/넥계산기!$B$18,0),IF(((B19-J19)/2)>넥계산기!$B$19,ROUNDUP(((B19-J19)/2)/넥계산기!$B$18,0),1))) | U19: =IF(B19="","",(J19/B19)^4) | V19: =IF(B19="","",1/U19) | W19: =IF(B19="","",E19/B19) | X19: =IF(B19="","",IF(B19<0.5,"⛔ 미적용",IF(B19<2,"🔴 개별 확인",IF(B19<2.5,"🟡 개별(유효장 길면)",IF(B19<8,"🟢 기본 적용","🟡 여유 확인"))))) | Y19: =IF(B19="","",IF(F19="","전장 입력",F19-IF((E19>D19),Q19+P19,D19+(G19-B19)/(2*TAN(RADIANS(H19)))))) | Z19: =IF(B19="","",IF((E19>D19),(N19+O19+P19)/넥계산기!$B$20,(N19+L19)/넥계산기!$B$20))
J20: =IF(B20="","",IF(I20="",B20-넥계산기!$B$13,I20)) | K20: =IF(B20="","",IF((E20>D20),"3섹션 연장","단일")) | L20: =IF(B20="","",((B20-J20)/2)/TAN(RADIANS(H20))) | M20: =IF(B20="","",-(C20+넥계산기!$B$14)) | N20: =IF(B20="","",IF((E20>D20),D20-(C20+넥계산기!$B$14),Q20-(C20+넥계산기!$B$14))) | O20: =IF(B20="","",IF((E20>D20),Q20-D20,"—")) | P20: =IF(B20="","",IF((E20>D20),(G20-J20)/(2*TAN(RADIANS(H20))),"—")) | Q20: =IF(B20="","",E20-L20) | R20: =IF(B20="","",IF((E20>D20),MIN(G20,B20+2*(Q20-D20)*TAN(RADIANS(H20))),"—")) | S20: =IF(B20="","",IF((E20>D20),(MIN(G20,B20+2*(Q20-D20)*TAN(RADIANS(H20)))-J20)/2,((B20-J20)/2))) | T20: =IF(B20="","",IF((E20>D20),ROUNDUP(S20/넥계산기!$B$18,0),IF(((B20-J20)/2)>넥계산기!$B$19,ROUNDUP(((B20-J20)/2)/넥계산기!$B$18,0),1))) | U20: =IF(B20="","",(J20/B20)^4) | V20: =IF(B20="","",1/U20) | W20: =IF(B20="","",E20/B20) | X20: =IF(B20="","",IF(B20<0.5,"⛔ 미적용",IF(B20<2,"🔴 개별 확인",IF(B20<2.5,"🟡 개별(유효장 길면)",IF(B20<8,"🟢 기본 적용","🟡 여유 확인"))))) | Y20: =IF(B20="","",IF(F20="","전장 입력",F20-IF((E20>D20),Q20+P20,D20+(G20-B20)/(2*TAN(RADIANS(H20)))))) | Z20: =IF(B20="","",IF((E20>D20),(N20+O20+P20)/넥계산기!$B$20,(N20+L20)/넥계산기!$B$20))
J21: =IF(B21="","",IF(I21="",B21-넥계산기!$B$13,I21)) | K21: =IF(B21="","",IF((E21>D21),"3섹션 연장","단일")) | L21: =IF(B21="","",((B21-J21)/2)/TAN(RADIANS(H21))) | M21: =IF(B21="","",-(C21+넥계산기!$B$14)) | N21: =IF(B21="","",IF((E21>D21),D21-(C21+넥계산기!$B$14),Q21-(C21+넥계산기!$B$14))) | O21: =IF(B21="","",IF((E21>D21),Q21-D21,"—")) | P21: =IF(B21="","",IF((E21>D21),(G21-J21)/(2*TAN(RADIANS(H21))),"—")) | Q21: =IF(B21="","",E21-L21) | R21: =IF(B21="","",IF((E21>D21),MIN(G21,B21+2*(Q21-D21)*TAN(RADIANS(H21))),"—")) | S21: =IF(B21="","",IF((E21>D21),(MIN(G21,B21+2*(Q21-D21)*TAN(RADIANS(H21)))-J21)/2,((B21-J21)/2))) | T21: =IF(B21="","",IF((E21>D21),ROUNDUP(S21/넥계산기!$B$18,0),IF(((B21-J21)/2)>넥계산기!$B$19,ROUNDUP(((B21-J21)/2)/넥계산기!$B$18,0),1))) | U21: =IF(B21="","",(J21/B21)^4) | V21: =IF(B21="","",1/U21) | W21: =IF(B21="","",E21/B21) | X21: =IF(B21="","",IF(B21<0.5,"⛔ 미적용",IF(B21<2,"🔴 개별 확인",IF(B21<2.5,"🟡 개별(유효장 길면)",IF(B21<8,"🟢 기본 적용","🟡 여유 확인"))))) | Y21: =IF(B21="","",IF(F21="","전장 입력",F21-IF((E21>D21),Q21+P21,D21+(G21-B21)/(2*TAN(RADIANS(H21)))))) | Z21: =IF(B21="","",IF((E21>D21),(N21+O21+P21)/넥계산기!$B$20,(N21+L21)/넥계산기!$B$20))
J22: =IF(B22="","",IF(I22="",B22-넥계산기!$B$13,I22)) | K22: =IF(B22="","",IF((E22>D22),"3섹션 연장","단일")) | L22: =IF(B22="","",((B22-J22)/2)/TAN(RADIANS(H22))) | M22: =IF(B22="","",-(C22+넥계산기!$B$14)) | N22: =IF(B22="","",IF((E22>D22),D22-(C22+넥계산기!$B$14),Q22-(C22+넥계산기!$B$14))) | O22: =IF(B22="","",IF((E22>D22),Q22-D22,"—")) | P22: =IF(B22="","",IF((E22>D22),(G22-J22)/(2*TAN(RADIANS(H22))),"—")) | Q22: =IF(B22="","",E22-L22) | R22: =IF(B22="","",IF((E22>D22),MIN(G22,B22+2*(Q22-D22)*TAN(RADIANS(H22))),"—")) | S22: =IF(B22="","",IF((E22>D22),(MIN(G22,B22+2*(Q22-D22)*TAN(RADIANS(H22)))-J22)/2,((B22-J22)/2))) | T22: =IF(B22="","",IF((E22>D22),ROUNDUP(S22/넥계산기!$B$18,0),IF(((B22-J22)/2)>넥계산기!$B$19,ROUNDUP(((B22-J22)/2)/넥계산기!$B$18,0),1))) | U22: =IF(B22="","",(J22/B22)^4) | V22: =IF(B22="","",1/U22) | W22: =IF(B22="","",E22/B22) | X22: =IF(B22="","",IF(B22<0.5,"⛔ 미적용",IF(B22<2,"🔴 개별 확인",IF(B22<2.5,"🟡 개별(유효장 길면)",IF(B22<8,"🟢 기본 적용","🟡 여유 확인"))))) | Y22: =IF(B22="","",IF(F22="","전장 입력",F22-IF((E22>D22),Q22+P22,D22+(G22-B22)/(2*TAN(RADIANS(H22)))))) | Z22: =IF(B22="","",IF((E22>D22),(N22+O22+P22)/넥계산기!$B$20,(N22+L22)/넥계산기!$B$20))
... J25: =IF(B25="","",IF(I25="",B25-넥계산기!$B$13,I25)) | K25: =IF(B25="","",IF((E25>D25),"3섹션 연장","단일")) | L25: =IF(B25="","",((B25-J25)/2)/TAN(RADIANS(H25))) | M25: =IF(B25="","",-(C25+넥계산기!$B$14)) | N25: =IF(B25="","",IF((E25>D25),D25-(C25+넥계산기!$B$14),Q25-(C25+넥계산기!$B$14))) | O25: =IF(B25="","",IF((E25>D25),Q25-D25,"—")) | P25: =IF(B25="","",IF((E25>D25),(G25-J25)/(2*TAN(RADIANS(H25))),"—")) | Q25: =IF(B25="","",E25-L25) | R25: =IF(B25="","",IF((E25>D25),MIN(G25,B25+2*(Q25-D25)*TAN(RADIANS(H25))),"—")) | S25: =IF(B25="","",IF((E25>D25),(MIN(G25,B25+2*(Q25-D25)*TAN(RADIANS(H25)))-J25)/2,((B25-J25)/2))) | T25: =IF(B25="","",IF((E25>D25),ROUNDUP(S25/넥계산기!$B$18,0),IF(((B25-J25)/2)>넥계산기!$B$19,ROUNDUP(((B25-J25)/2)/넥계산기!$B$18,0),1))) | U25: =IF(B25="","",(J25/B25)^4) | V25: =IF(B25="","",1/U25) | W25: =IF(B25="","",E25/B25) | X25: =IF(B25="","",IF(B25<0.5,"⛔ 미적용",IF(B25<2,"🔴 개별 확인",IF(B25<2.5,"🟡 개별(유효장 길면)",IF(B25<8,"🟢 기본 적용","🟡 여유 확인"))))) | Y25: =IF(B25="","",IF(F25="","전장 입력",F25-IF((E25>D25),Q25+P25,D25+(G25-B25)/(2*TAN(RADIANS(H25)))))) | Z25: =IF(B25="","",IF((E25>D25),(N25+O25+P25)/넥계산기!$B$20,(N25+L25)/넥계산기!$B$20))

Sheet 설명·근거
A1: 수식 · 근거 · 신뢰도
A3: 항목 | B3: 수식 / 내용 | C3: 신뢰도 | D3: 출처
A4: 넥 지름 d | B4: d = D − 0.15 (지름 기준, 한쪽 0.075 mm). 입력하면 입력값 우선 | C4: 사내 경험값 (근거 D4 1건) | D4: decisions 2026-10-19 (6) · AFCY_2krb040120s06.tom (2016)
A5: Washout 길이 | B5: wo = (D − d) ÷ 2 ÷ tan θ | C5: 계산값 | D5: iGrind Grinding Manual §30.9 [VEN-ANCA-IGRIND-CYCLES]
A6: X Start | B6: X Start = −(L1 + 여유), 여유 기본 0.1 mm | C6: 사내 경험값 | D6: 2JJCR 기존·확정안 −4.1
A7: 단일 섹션 Step length | B7: Step = (L2 − wo) − (L1 + 여유). Step length 는 washout 제외 | C7: 제조사 기준 (정의) / 계산값 | D7: [VEN-ANCA-IGRIND-CYCLES] §30.9
A8: 단일 섹션 조건 | B8: L2(목표) ≤ L2(블랭크). 넥 끝의 θ washout 이 기존 테이퍼 선과 겹쳐 테이퍼 재연삭 불필요 | C8: 계산값 | D8: worklog 2026-10-19 (#4)
A9: 3섹션 조건 | B9: L2(목표) > L2(블랭크) — 새 테이퍼가 기존 테이퍼와 평행하게 안쪽으로 밀려 생크를 깎음 | C9: 계산값
A10: S1 | B10: X Start → −L2(블랭크), 길이 = L2(블랭크) − (L1 + 여유), 정삭만, Start OD = D | C10: 추정값 (시뮬·실측 전) | D10: iGrind 넥 페이지 테스트 제품 절
A11: S2 | B11: −L2(블랭크) → −(L2 − wo), 길이 = L2 − wo − L2(블랭크), 황삭 켬, Start OD = MIN(S, D + 2 × (L2 − wo − L2(블랭크)) × tan θ) | C11: 추정값 | D11: 같은 절
A12: S3 | B12: −(L2 − wo) 에서 θ 테이퍼, 길이 = (S − d) ÷ (2 tan θ), Final Ø = d (EOT 쪽), Start OD = S | C12: 추정값 — Step taper 정의 확인 필요 | D12: 같은 절
A13: 최대 반경 제거 | B13: 단일 = Δr · 연장 = (S2 Start OD − d) ÷ 2 | C13: 계산값
A14: 황삭 패스 | B14: ROUNDUP(최대 제거 ÷ 1패스 반경 절입). 시작 0.05 → 이상 없으면 0.075 | C14: 추정값 — 시험 필요 | D14: worklog 2026-10-19 (#4)
A15: 굽힘 강성 비 | B15: (d ÷ D)⁴ — I = π d⁴ ÷ 64, 외팔보 처짐 δ = F L³ ÷ (3 E I) | C15: 계산값 (재료역학 기본식) | D15: [ACA-GERE-MECHMAT] · standards/넥-지름-기준-굽힘강성표
A16: 적용 구분 경계 | B16: D < 0.5 ⛔ · < 2 🔴 · < 2.5 🟡 · < 8 🟢 · ≥ 8 🟡 | C16: 추정값 (잠정) | D16: 강성 참조표 §1
A17: Vc | B17: Vc = π × 휠 지름 × N ÷ 60000. 사내 실사용 16.8~19.6 m/s, 사내 상한 25 m/s, >30 m/s 경고 | C17: 제조사 기준 (범위) / 사내 기준 | D17: [VEN-NORTON-WINTER-2023] · CLAUDE.md §2
A18: 시간 | B18: 정삭 1패스 = 연삭 길이 ÷ 이송. 2JJCR 계산 7.95분 vs CIM3D 3:15 불일치 미결 | C18: 추정값 | D18: iGrind 넥 페이지 §4·미결 2
A20: 검산 1 — 2JJCR 040 010 200 | B20: D4 · L1 4 · L2 20 · S6 · θ15 · d 3.85 → wo 0.280 · X Start −4.100 · Step 15.620 · 넥 끝 −19.720 · 7.95분 | C20: 위키 값과 일치해야 함 | D20: cadcam/iGrind-원통연삭-넥가공-2JJCR040010200 §2
A21: 검산 2 — 테스트 D4 L2 8 → 14 | B21: S1 −4.1 / 3.90 · S2 −8.0 / 5.72 · Start OD 6.0 · S3 −13.72 / 4.01 → −17.73 · 최대 1.075 · 0.05 mm → 22패스 | C21: 위키 값과 일치해야 함 | D21: 같은 페이지 테스트 제품 절
A23: 미결 (확인 필요) | B23: ① Step taper 한쪽/양쪽·부호 ② 황삭 절입이 반경/직경 기준인지 ③ Finish stock 1.333 의미 ④ 7.95분 vs 3:15 ⑤ 정삭 휠 지름·폭 ⑥ A축 최대 rpm ⑦ Allow Wheel Overhang 공식 정의 | D23: iGrind 넥 페이지 §5 미결
A24: 안전 | B24: AI 제시 수치는 참고값. 신규 조건은 CIM3D → 시험 1개 → 측정 → 검증. 양산 적용은 현장 최종 판단 | D24: CLAUDE.md §2 조건 적용 안전 규칙

Sheet 변경이력
A1: 변경 이력 (기존 값 삭제 금지)
A3: 날짜 | B3: 내용 | C3: 사유 | D3: 양산 적용
A4: 2026-10-20 | B4: v1 신규 — 단일 섹션(washout 연결) · 3섹션(넥 연장) 자동 판별, 가능성 비교 시트, 검산 2건 일치 | C4: 한경준님 요청 — 날장·L2·전장·D·d·S 별 iGrind 입력값 계산 | D4: ❌ 미적용 (계산 도구)
